Workbook

Sheet Synthèse
A1: M2 — essais sur carte du 2026-09-26
A2: Contrôleur BLDC A2N · STM32G473 + DRV8304 · moteur de type gimbal · état de référence : STATUS.md (fait autorité)
A4: Étape | B4: Intitulé | C4: État au 2026-09-26 | D4: Critère (controller-2/AGENTS.md §5) | E4: Résultat chiffré | F4: Date(s) | G4: Onglet
A5: 2 | B5: DRV8304 : SPI, registres, nFAULT | C5: Validée (revalidée après réparation du SPI) | D5: Écriture puis relecture cohérente d'un registre, fautes remontées | E5: DRV.PROBE passe ; registres relus aux valeurs de reset ; gain des amplis relu à 20 V/V ; une écriture (VREF_DIV, SPI_CAL) change la mesure analogique. Chemin nFAULT → coupure MOE non déclenché physiquement (décision utilisateur) | F5: 2026-09-16 ; revalidée 2026-09-26 | G5: —
A6: 3 | B6: PWM à vide, haute impédance, temps mort | C6: Validée | D6: Formes correctes à l'oscilloscope, aucune conduction croisée | E6: 3 bras complémentaires à 20 kHz, temps mort 500 ns aux deux fronts, 20/50/80 % suivis | F6: 2026-09-18 | G6: —
A7: 4 | B7: ADC synchrone PWM, offsets des amplis | C7: Validée | D7: Offsets stables moteur à l'arrêt, bruit mesuré et documenté | E7: Zéro à 1–11 counts de la mi-échelle, répétable à ±1 count ; σ 1,4–2,0 counts (CAL levé). Depuis le 2026-09-26 : zéro mesuré hors CAL à chaque démarrage | F7: 2026-09-21 ; zéro hors CAL 2026-09-26 | G7: Zéro courant
A8: 5 | B8: Mesure des courants sous rapport cyclique fixe | C8: En cours — somme tenue ; échelle absolue estimée à ±15 % | D8: Σ Ia+Ib+Ic ≈ 0 ; cohérence avec le courant d'alimentation | E8: Somme 4,5 % rms / 5,8 % pire après correction des gains (41,8 % / 74,8 % brute). Gains relatifs à A : B 0,656, C 1,195. Protections éprouvées : pic 162 counts pour une limite de 500. Courant d'alimentation cohérent sur paliers de 10 s : échelle ≈ 1,82 mA/count corrigé (bilan 0,283 W fourni / 0,28 W en I²R) | F8: 2026-09-26 | G8: Étape 5 — courants ; Capture 600-500-500 ; Gains ; Étape 7 — R, L, échelle
A9: 6 | B9: AS5600 en DMA 1 MHz + extrapolation | C9: Verte à titre provisoire | D9: Angle monotone à la main, aucun blocage de l'ISR, retard total mesuré | E9: Transfert 57 µs, un échantillon toutes les 59 µs ; réserve aimant levée le 2026-09-26 (validité fondée sur la magnitude du champ) | F9: 2026-09-21 ; réserve levée 2026-09-26 | G9: —
A10: 7 | B10: Identification R et L de phase | C10: En cours — valeurs obtenues, stockage NVM non implémenté | D10: Valeurs plausibles, stockées en NVM | E10: R ≈ 5,4 Ω entre A et (B∥C) (5,42 recalculé, 5,44 communiqué), ≈ 3,6 Ω par phase ; τ ≈ 0,3 ms ⇒ L ≈ 1,6 mH entre A et (B∥C), ≈ 1,1 mH par phase (±25 %). Échelle du courant ±15 % | F10: 2026-09-26 | G10: Étape 7 — R, L, échelle
A11: 8 | B11: Alignement et offset électrique du capteur | C11: Validée | D11: Offset reproductible entre deux calibrations | E11: φ = 178,0° / 178,1° / 178,1° (essais 2 à 4, le dernier après redémarrage) : reproductible à 0,1° électrique | F11: 2026-09-26 | G11: Étapes 9 et 8
A12: 9 | B12: Nombre de paires de pôles | C12: Validée | D12: Valeur entière stable sur plusieurs essais | E12: p = 6,960 / 6,966 / 6,965 / 6,962 → 7 paires sur 4 essais ; sens inverse | F12: 2026-09-26 | G12: Étapes 9 et 8
A14: Réserves et points ouverts
A15: • | B15: Échelle absolue du courant : estimée le 2026-09-26 par paliers de 10 s et ampèremètre, ≈ 1,82 mA par count corrigé (nominal 4,03), ±15 % (lecture « environ » de l'ampèremètre). Toutes les voies lisent trop haut (A ×1,86, B ×1,22, C ×2,2) : résistances parasites dans le chemin de mesure des shunts. La limite de 500 counts vaut donc ≈ 0,9 A réels et non 2 A — plus stricte, sans danger, non relevée faute de mesure plus précise.
A16: • | B16: Critère « cohérence avec le courant d'alimentation » de l'étape 5 : tenu par le modèle I_alim = écart effectif × Ia + Ig et le bilan de puissance, mais sur une seule lecture approximative par palier — à confirmer par une mesure plus précise.
A17: • | B17: Zone morte à 2048 : au repos aucune voie ne descend sous la mi-échelle ; 95,2 % des échantillons de C et 11,7 % de B valent exactement 2048. Hypothèse non vérifiée : écrêtage de la sortie de l'ampli du DRV8304 à la référence. À comprendre avant d'asservir de petits courants.
A18: • | B18: Étape 7 : R et L obtenus, mais ni R, L, φ ni p ne sont stockés dans le firmware (mémoire non volatile pas encore implémentée).
A19: • | B19: Chemin nFAULT → coupure MOE non déclenché physiquement (décision du 2026-09-26) ; watchdog IWDG reporté.
A20: • | B20: Incohérences relevées entre les données brutes et STATUS.md : voir l'onglet « Méthode », section « Points de vigilance ».

Sheet Conditions
A1: Conditions d'essai — rails, boucle et limites
A2: Relevé console du 2026-09-26 (valeurs absentes des fichiers bruts)
A4: Grandeur | B4: Valeur | C4: Unité | D4: Source
A5: Tension d'entrée | B5: 15.18 | C5: V | D5: relevé console
A6: Rail moteur | B6: 14.88 | C6: V | D6: relevé console
A7: Rail 5 V | B7: 4.93 | C7: V | D7: relevé console
A8: Rail 3,3 V | B8: 3.31 | C8: V | D8: relevé console
A9: VREF | B9: 3.307 | C9: V | D9: relevé console
A10: Température MCU (min) | B10: 32 | C10: °C | D10: relevé console
A11: Température MCU (max) | B11: 37 | C11: °C | D11: relevé console
A12: Fréquence de boucle | B12: 20 | C12: kHz | D12: relevé console
A13: Durée ISR typique | B13: 3.57 | C13: µs | D13: relevé console
A14: Durée ISR pire | B14: 6.09 | C14: µs | D14: relevé console
A15: Charge ISR au pire (durée pire / période 50 µs) | B15: =B14/(1000/B12) | C15: — | D15: calcul
A16: Télémétrie | B16: 500 | C16: Hz (sans trou) | D16: relevé console
A17: Scope : profondeur | B17: 2048 | C17: points | D17: relevé console
A18: Scope : signaux | B18: 4 | C18: signaux | D18: relevé console
A19: Limite de surintensité | B19: 500 | C19: counts corrigés (échelle voie C) | D19: relevé console
A20: Rapport cyclique min | B20: 0 | C20: ‰ | D20: relevé console
A21: Rapport cyclique max | B21: 800 | C21: ‰ | D21: relevé console
A22: Écart max entre bras | B22: 100 | C22: ‰ | D22: relevé console
A23: Durée d'impulsion min | B23: 1 | C23: ms | D23: relevé console
A24: Durée d'impulsion max | B24: 200 | C24: ms | D24: relevé console
A25: Échelle nominale du courant (20 V/V × 10 mΩ) | B25: 4.03 | C25: mA / count | D25: relevé console
A26: Limite de surintensité à l'échelle nominale (majorant d'origine) | B26: =B19*B25/1000 | C26: A | D26: calcul
A27: Résistance A → (B∥C), estimation initiale (remplacée à l'étape 7 par ≈ 5,4 Ω) | B27: 7 | C27: Ω (≈) | D27: relevé console
A28: Résistance par phase, estimation initiale (× 2/3) | B28: =B27*2/3 | C28: Ω (≈) | D28: calcul
A29: Limite de surintensité en courant réel (échelle de l'étape 7) | B29: ='Étape 7 — R, L, échelle'!F43 | C29: A (±15 %) | D29: calcul
A32: Police bleue : valeur saisie (relevé console) ; police noire : calcul.

Sheet Étape 5 — courants
A1: Étape 5 — deltas de courant par impulsion de 50 ms
A2: Delta = moyenne 30–50 ms − moyenne 60–100 ms (repos), par voie ; counts centrés ; mA à l'échelle nominale (Conditions!B25), SANS correction de gain
A4: Série | B4: Échantillonnage ADC | C4: Horodatage | D4: Duty A (‰) | E4: Duty B (‰) | F4: Duty C (‰) | G4: Écart (‰) | H4: Phase dominante | I4: dA (counts) | J4: dB (counts) | K4: dC (counts) | L4: Σ (counts) | M4: Erreur de somme Σ/max|d| | N4: dA (mA nom.) | O4: dB (mA nom.) | P4: dC (mA nom.) | Q4: Excursion rotor (rad) | R4: Pic |i| (counts) | S4: Retenu / remarque
A5: 1 | B5: 6,5 cycles (180 ns) | C5: 1790433145270 | D5: 500 | E5: 500 | F5: 500 | G5: 0 | H5: — | I5: -0.87 | J5: -0.33 | K5: 0.02 | L5: =I5+J5+K5 | M5: =IF(MAX(ABS(I5),ABS(J5),ABS(K5))<5,"s.o.",L5/MAX(ABS(I5),ABS(J5),ABS(K5))) | N5: =I5*Conditions!$B$25 | O5: =J5*Conditions!$B$25 | P5: =K5*Conditions!$B$25 | Q5: 0.03 | R5: 73 | S5: Écart nul : erreur de somme sans objet (dénominateur ≈ 1 count)
A6: 1 | B6: 6,5 cycles (180 ns) | C6: 1790433210889 | D6: 510 | E6: 500 | F6: 500 | G6: 10 | H6: A+ | I6: 5.53 | J6: -2.32 | K6: -4.28 | L6: =I6+J6+K6 | M6: =IF(MAX(ABS(I6),ABS(J6),ABS(K6))<5,"s.o.",L6/MAX(ABS(I6),ABS(J6),ABS(K6))) | N6: =I6*Conditions!$B$25 | O6: =J6*Conditions!$B$25 | P6: =K6*Conditions!$B$25 | Q6: 0.02 | R6: 64 | S6: Deltas de quelques counts : erreur dominée par le bruit
A7: 1 | B7: 6,5 cycles (180 ns) | C7: 1790433242201 | D7: 530 | E7: 500 | F7: 500 | G7: 30 | H7: A+ | I7: 18.13 | J7: -6.13 | K7: -10.34 | L7: =I7+J7+K7 | M7: =IF(MAX(ABS(I7),ABS(J7),ABS(K7))<5,"s.o.",L7/MAX(ABS(I7),ABS(J7),ABS(K7))) | N7: =I7*Conditions!$B$25 | O7: =J7*Conditions!$B$25 | P7: =K7*Conditions!$B$25 | Q7: 0.082 | R7: 72
A8: 1 | B8: 6,5 cycles (180 ns) | C8: 1790433262784 | D8: 550 | E8: 500 | F8: 500 | G8: 50 | H8: A+ | I8: 39.11 | J8: -12.41 | K8: -10.67 | L8: =I8+J8+K8 | M8: =IF(MAX(ABS(I8),ABS(J8),ABS(K8))<5,"s.o.",L8/MAX(ABS(I8),ABS(J8),ABS(K8))) | N8: =I8*Conditions!$B$25 | O8: =J8*Conditions!$B$25 | P8: =K8*Conditions!$B$25 | Q8: 0.146 | R8: 89 | S8: Rotor en mouvement (0,15 rad) pendant l'impulsion — cause probable de l'erreur élevée
A9: 1 | B9: 6,5 cycles (180 ns) | C9: 1790433265615 | D9: 570 | E9: 500 | F9: 500 | G9: 70 | H9: A+ | I9: 67.38 | J9: -19.69 | K9: -37.41 | L9: =I9+J9+K9 | M9: =IF(MAX(ABS(I9),ABS(J9),ABS(K9))<5,"s.o.",L9/MAX(ABS(I9),ABS(J9),ABS(K9))) | N9: =I9*Conditions!$B$25 | O9: =J9*Conditions!$B$25 | P9: =K9*Conditions!$B$25 | Q9: 0.019 | R9: 126
A10: 1 | B10: 6,5 cycles (180 ns) | C10: 1790433268460 | D10: 600 | E10: 500 | F10: 500 | G10: 100 | H10: A+ | I10: 106.78 | J10: -21.11 | K10: -60.21 | L10: =I10+J10+K10 | M10: =IF(MAX(ABS(I10),ABS(J10),ABS(K10))<5,"s.o.",L10/MAX(ABS(I10),ABS(J10),ABS(K10))) | N10: =I10*Conditions!$B$25 | O10: =J10*Conditions!$B$25 | P10: =K10*Conditions!$B$25 | Q10: 0.019 | R10: 162
A11: 1 | B11: 6,5 cycles (180 ns) | C11: 1790433310434 | D11: 500 | E11: 600 | F11: 500 | G11: 100 | H11: B+ | I11: -58.9 | J11: 73.67 | K11: -41.56 | L11: =I11+J11+K11 | M11: =IF(MAX(ABS(I11),ABS(J11),ABS(K11))<5,"s.o.",L11/MAX(ABS(I11),ABS(J11),ABS(K11))) | N11: =I11*Conditions!$B$25 | O11: =J11*Conditions!$B$25 | P11: =K11*Conditions!$B$25 | Q11: 0.424 | R11: 117 | S11: Rotor en mouvement pendant l'impulsion — non stationnaire, écarté
A12: 1 | B12: 6,5 cycles (180 ns) | C12: 1790433312256 | D12: 500 | E12: 500 | F12: 600 | G12: 100 | H12: C+ | I12: -30.44 | J12: -21.89 | K12: 117.86 | L12: =I12+J12+K12 | M12: =IF(MAX(ABS(I12),ABS(J12),ABS(K12))<5,"s.o.",L12/MAX(ABS(I12),ABS(J12),ABS(K12))) | N12: =I12*Conditions!$B$25 | O12: =J12*Conditions!$B$25 | P12: =K12*Conditions!$B$25 | Q12: 0.298 | R12: 158 | S12: Rotor en mouvement pendant l'impulsion — non stationnaire, écarté
A13: 2 | B13: 47,5 cycles (1,32 µs) | C13: 1790433423381 | D13: 600 | E13: 500 | F13: 500 | G13: 100 | H13: A+ | I13: 101.4 | J13: -18.68 | K13: -74.38 | L13: =I13+J13+K13 | M13: =IF(MAX(ABS(I13),ABS(J13),ABS(K13))<5,"s.o.",L13/MAX(ABS(I13),ABS(J13),ABS(K13))) | N13: =I13*Conditions!$B$25 | O13: =J13*Conditions!$B$25 | P13: =K13*Conditions!$B$25 | Q13: 0.289 | R13: 144 | S13: 1re impulsion : alignement du rotor, non retenue
A14: 2 | B14: 47,5 cycles (1,32 µs) | C14: 1790433425069 | D14: 600 | E14: 500 | F14: 500 | G14: 100 | H14: A+ | I14: 103.32 | J14: -35.1 | K14: -64.09 | L14: =I14+J14+K14 | M14: =IF(MAX(ABS(I14),ABS(J14),ABS(K14))<5,"s.o.",L14/MAX(ABS(I14),ABS(J14),ABS(K14))) | N14: =I14*Conditions!$B$25 | O14: =J14*Conditions!$B$25 | P14: =K14*Conditions!$B$25 | Q14: 0.059 | R14: 158 | S14: Retenu (rotor aligné)
A15: 2 | B15: 47,5 cycles (1,32 µs) | C15: 1790433426759 | D15: 500 | E15: 600 | F15: 500 | G15: 100 | H15: B+ | I15: -62.85 | J15: 64.77 | K15: -48.28 | L15: =I15+J15+K15 | M15: =IF(MAX(ABS(I15),ABS(J15),ABS(K15))<5,"s.o.",L15/MAX(ABS(I15),ABS(J15),ABS(K15))) | N15: =I15*Conditions!$B$25 | O15: =J15*Conditions!$B$25 | P15: =K15*Conditions!$B$25 | Q15: 0.391 | R15: 119 | S15: 1re impulsion : alignement du rotor, non retenue
A16: 2 | B16: 47,5 cycles (1,32 µs) | C16: 1790433428476 | D16: 500 | E16: 600 | F16: 500 | G16: 100 | H16: B+ | I16: -54 | J16: 66.49 | K16: -62.56 | L16: =I16+J16+K16 | M16: =IF(MAX(ABS(I16),ABS(J16),ABS(K16))<5,"s.o.",L16/MAX(ABS(I16),ABS(J16),ABS(K16))) | N16: =I16*Conditions!$B$25 | O16: =J16*Conditions!$B$25 | P16: =K16*Conditions!$B$25 | Q16: 0.011 | R16: 96 | S16: Retenu (rotor aligné)
A17: 2 | B17: 47,5 cycles (1,32 µs) | C17: 1790433430197 | D17: 500 | E17: 500 | F17: 600 | G17: 100 | H17: C+ | I17: -31.82 | J17: -35.25 | K17: 110.19 | L17: =I17+J17+K17 | M17: =IF(MAX(ABS(I17),ABS(J17),ABS(K17))<5,"s.o.",L17/MAX(ABS(I17),ABS(J17),ABS(K17))) | N17: =I17*Conditions!$B$25 | O17: =J17*Conditions!$B$25 | P17: =K17*Conditions!$B$25 | Q17: 0.376 | R17: 130 | S17: 1re impulsion : alignement du rotor, non retenue
A18: 2 | B18: 47,5 cycles (1,32 µs) | C18: 1790433431933 | D18: 500 | E18: 500 | F18: 600 | G18: 100 | H18: C+ | I18: -50.81 | J18: -32.03 | K18: 112.4 | L18: =I18+J18+K18 | M18: =IF(MAX(ABS(I18),ABS(J18),ABS(K18))<5,"s.o.",L18/MAX(ABS(I18),ABS(J18),ABS(K18))) | N18: =I18*Conditions!$B$25 | O18: =J18*Conditions!$B$25 | P18: =K18*Conditions!$B$25 | Q18: 0.023 | R18: 121 | S18: Retenu (rotor aligné)
A19: 2 | B19: 47,5 cycles (1,32 µs) | C19: 1790433490443 | D19: 400 | E19: 500 | F19: 500 | G19: 100 | H19: A− | I19: -102.82 | J19: 37.67 | K19: 49.19 | L19: =I19+J19+K19 | M19: =IF(MAX(ABS(I19),ABS(J19),ABS(K19))<5,"s.o.",L19/MAX(ABS(I19),ABS(J19),ABS(K19))) | N19: =I19*Conditions!$B$25 | O19: =J19*Conditions!$B$25 | P19: =K19*Conditions!$B$25 | Q19: 0.267 | R19: 123 | S19: 1re impulsion : alignement du rotor, non retenue
A20: 2 | B20: 47,5 cycles (1,32 µs) | C20: 1790433492160 | D20: 400 | E20: 500 | F20: 500 | G20: 100 | H20: A− | I20: -103.88 | J20: 31.26 | K20: 61.15 | L20: =I20+J20+K20 | M20: =IF(MAX(ABS(I20),ABS(J20),ABS(K20))<5,"s.o.",L20/MAX(ABS(I20),ABS(J20),ABS(K20))) | N20: =I20*Conditions!$B$25 | O20: =J20*Conditions!$B$25 | P20: =K20*Conditions!$B$25 | Q20: 0.152 | R20: 119 | S20: Retenu (rotor aligné)
A21: 2 | B21: 47,5 cycles (1,32 µs) | C21: 1790433493812 | D21: 500 | E21: 400 | F21: 500 | G21: 100 | H21: B− | I21: 18.9 | J21: -45.19 | K21: 55.93 | L21: =I21+J21+K21 | M21: =IF(MAX(ABS(I21),ABS(J21),ABS(K21))<5,"s.o.",L21/MAX(ABS(I21),ABS(J21),ABS(K21))) | N21: =I21*Conditions!$B$25 | O21: =J21*Conditions!$B$25 | P21: =K21*Conditions!$B$25 | Q21: 0.617 | R21: 112 | S21: 1re impulsion : alignement du rotor, non retenue
A22: 2 | B22: 47,5 cycles (1,32 µs) | C22: 1790433495531 | D22: 500 | E22: 400 | F22: 500 | G22: 100 | H22: B− | I22: 52.3 | J22: -68.17 | K22: 54.29 | L22: =I22+J22+K22 | M22: =IF(MAX(ABS(I22),ABS(J22),ABS(K22))<5,"s.o.",L22/MAX(ABS(I22),ABS(J22),ABS(K22))) | N22: =I22*Conditions!$B$25 | O22: =J22*Conditions!$B$25 | P22: =K22*Conditions!$B$25 | Q22: 0.034 | R22: 100 | S22: Retenu (rotor aligné)
... A24: 2 | B24: 47,5 cycles (1,32 µs) | C24: 1790433498982 | D24: 500 | E24: 500 | F24: 400 | G24: 100 | H24: C− | I24: 49.02 | J24: 32.08 | K24: -121.24 | L24: =I24+J24+K24 | M24: =IF(MAX(ABS(I24),ABS(J24),ABS(K24))<5,"s.o.",L24/MAX(ABS(I24),ABS(J24),ABS(K24))) | N24: =I24*Conditions!$B$25 | O24: =J24*Conditions!$B$25 | P24: =K24*Conditions!$B$25 | Q24: 0.056 | R24: 128 | S24: Retenu (rotor aligné)
A26: Lignes grises : impulsions non retenues pour l'analyse. dA/dB/dC, excursion et pic calculés depuis les CSV (2048 points à 20 kHz) ; colonnes L à P : formules.
A27: Erreur « s.o. » : dénominateur < 5 counts (écart nul). Excursion rotor = max − min de pos_rad sur la capture. Pic = max |i| toutes voies sur la capture.
A29: Rampe A dominante (A+) — erreur de somme vs écart de rapport cyclique
A30: Écart (‰) | B30: Série 1 : 6,5 cycles | C30: Série 2 : 47,5 cycles (retenu)
A31: 10 | B31: =M6
A32: 30 | B32: =M7
A33: 50 | B33: =M8
A34: 70 | B34: =M9
A35: 100 | B35: =M10 | C35: =M14
A37: Le point à 50 ‰ (41 %) coïncide avec un rotor en mouvement : la rampe n'est pas monotone.

Sheet Capture 600-500-500
A1: Capture typique — 600/500/500, série 2 (47,5 cycles), impulsion retenue
A2: Fichier step5_600_500_500_50ms_1790433425069.csv, sous-échantillonné 1 point sur 4 (0,2 ms) ; counts centrés, sans correction de gain
A4: t (ms) | B4: ia (counts) | C4: ib (counts) | D4: ic (counts) | E4: Σ (counts) | F4: pos (rad)
A5: 0 | B5: 14 | C5: 3 | D5: 0 | E5: =B5+C5+D5 | F5: -0.1902
A6: 0.2 | B6: 9 | C6: 8 | D6: 0 | E6: =B6+C6+D6 | F6: -0.1902
A7: 0.4 | B7: 9 | C7: 3 | D7: 0 | E7: =B7+C7+D7 | F7: -0.1902
A8: 0.6 | B8: 12 | C8: 3 | D8: 0 | E8: =B8+C8+D8 | F8: -0.1902
A9: 0.8 | B9: 14 | C9: 8 | D9: 0 | E9: =B9+C9+D9 | F9: -0.1886
A10: 1 | B10: 11 | C10: 7 | D10: 0 | E10: =B10+C10+D10 | F10: -0.1902
A11: 1.2 | B11: 12 | C11: 6 | D11: 0 | E11: =B11+C11+D11 | F11: -0.1887
A12: 1.4 | B12: 11 | C12: 10 | D12: 1 | E12: =B12+C12+D12 | F12: -0.1887
A13: 1.6 | B13: 13 | C13: 2 | D13: 0 | E13: =B13+C13+D13 | F13: -0.1902
A14: 1.8 | B14: 12 | C14: 6 | D14: 0 | E14: =B14+C14+D14 | F14: -0.1902
A15: 2 | B15: 30 | C15: 0 | D15: 0 | E15: =B15+C15+D15 | F15: -0.1902
A16: 2.2 | B16: 73 | C16: 0 | D16: -37 | E16: =B16+C16+D16 | F16: -0.1887
... A25: 4 | B25: 115 | C25: -28 | D25: -63 | E25: =B25+C25+D25 | F25: -0.1902
A26: 4.2 | B26: 113 | C26: -35 | D26: -62 | E26: =B26+C26+D26 | F26: -0.1902 | H26: Impulsion de 50 ms démarrant ~2 ms après le début ; fenêtre de régime 30–50 ms, de repos 60–100 ms.
A27: 4.4 | B27: 113 | C27: -30 | D27: -57 | E27: =B27+C27+D27 | F27: -0.1902
A28: 4.6 | B28: 113 | C28: -33 | D28: -61 | E28: =B28+C28+D28 | F28: -0.1918
A29: 4.8 | B29: 113 | C29: -32 | D29: -58 | E29: =B29+C29+D29 | F29: -0.1918
A30: 5 | B30: 107 | C30: -32 | D30: -58 | E30: =B30+C30+D30 | F30: -0.1918
A31: 5.2 | B31: 115 | C31: -30 | D31: -55 | E31: =B31+C31+D31 | F31: -0.1918
A32: 5.4 | B32: 115 | C32: -29 | D32: -57 | E32: =B32+C32+D32 | F32: -0.1933
A33: 5.6 | B33: 117 | C33: -39 | D33: -56 | E33: =B33+C33+D33 | F33: -0.1918
A34: 5.8 | B34: 112 | C34: -30 | D34: -62 | E34: =B34+C34+D34 | F34: -0.1934
A35: 6 | B35: 115 | C35: -33 | D35: -61 | E35: =B35+C35+D35 | F35: -0.1918
A36: 6.2 | B36: 114 | C36: -31 | D36: -58 | E36: =B36+C36+D36 | F36: -0.1918
A37: 6.4 | B37: 107 | C37: -37 | D37: -61 | E37: =B37+C37+D37 | F37: -0.1933
A38: 6.6 | B38: 118 | C38: -35 | D38: -57 | E38: =B38+C38+D38 | F38: -0.1933
... A516: 102.2 | B516: 9 | C516: 7 | D516: 0 | E516: =B516+C516+D516 | F516: -0.2117

Sheet Gains
A1: Gains relatifs des voies de courant — campagne de 18 impulsions et vérification
A2: Échantillonnage 47,5 cycles ; delta = moyenne 30–50 ms − repos 60–100 ms ; 1re impulsion de chaque configuration écartée (alignement du rotor)
A3: Modèle : Ia+Ib+Ic = 0 ⇒ dA + x·dB + y·dC = 0, x = 1/gB, y = 1/gC ; moindres carrés sur toutes les impulsions (équations normales 2×2, recalculées ci-contre par formules).
K4: Ajustement
A5: Run | B5: # | C5: Configuration (‰) | D5: dA (counts) | E5: dB (counts) | F5: dC (counts) | G5: Σ brute (counts) | H5: Erreur brute | I5: Erreur corrigée | K5: Grandeur | L5: Run 1 (sans corr.) | M5: Run 2 (avec corr.)
A6: 1 | B6: 1 | C6: 600/500/500 | D6: 103.007 | E6: -31.381 | F6: -69.46 | G6: =D6+E6+F6 | H6: =G6/MAX(ABS(D6),ABS(E6),ABS(F6)) | I6: =(D6+E6*L$12+F6*L$13)/MAX(ABS(D6),ABS(E6*L$12),ABS(F6*L$13)) | K6: Σ dB² | L6: =SUMPRODUCT($E$6:$E$23,$E$6:$E$23) | M6: =SUMPRODUCT($E$27:$E$38,$E$27:$E$38)
A7: 1 | B7: 2 | C7: 600/500/500 | D7: 102.666 | E7: -32.233 | F7: -68.91 | G7: =D7+E7+F7 | H7: =G7/MAX(ABS(D7),ABS(E7),ABS(F7)) | I7: =(D7+E7*L$12+F7*L$13)/MAX(ABS(D7),ABS(E7*L$12),ABS(F7*L$13)) | K7: Σ dC² | L7: =SUMPRODUCT($F$6:$F$23,$F$6:$F$23) | M7: =SUMPRODUCT($F$27:$F$38,$F$27:$F$38)
A8: 1 | B8: 3 | C8: 600/500/500 | D8: 102.91 | E8: -32.601 | F8: -68.992 | G8: =D8+E8+F8 | H8: =G8/MAX(ABS(D8),ABS(E8),ABS(F8)) | I8: =(D8+E8*L$12+F8*L$13)/MAX(ABS(D8),ABS(E8*L$12),ABS(F8*L$13)) | K8: Σ dB·dC | L8: =SUMPRODUCT($E$6:$E$23,$F$6:$F$23) | M8: =SUMPRODUCT($E$27:$E$38,$F$27:$F$38)
A9: 1 | B9: 1 | C9: 400/500/500 | D9: -103.852 | E9: 35.656 | F9: 53.584 | G9: =D9+E9+F9 | H9: =G9/MAX(ABS(D9),ABS(E9),ABS(F9)) | I9: =(D9+E9*L$12+F9*L$13)/MAX(ABS(D9),ABS(E9*L$12),ABS(F9*L$13)) | K9: Σ dA·dB | L9: =SUMPRODUCT($D$6:$D$23,$E$6:$E$23) | M9: =SUMPRODUCT($D$27:$D$38,$E$27:$E$38)
A10: 1 | B10: 2 | C10: 400/500/500 | D10: -103.929 | E10: 31.449 | F10: 60.024 | G10: =D10+E10+F10 | H10: =G10/MAX(ABS(D10),ABS(E10),ABS(F10)) | I10: =(D10+E10*L$12+F10*L$13)/MAX(ABS(D10),ABS(E10*L$12),ABS(F10*L$13)) | K10: Σ dA·dC | L10: =SUMPRODUCT($D$6:$D$23,$F$6:$F$23) | M10: =SUMPRODUCT($D$27:$D$38,$F$27:$F$38)
A11: 1 | B11: 3 | C11: 400/500/500 | D11: -104.415 | E11: 31.331 | F11: 60 | G11: =D11+E11+F11 | H11: =G11/MAX(ABS(D11),ABS(E11),ABS(F11)) | I11: =(D11+E11*L$12+F11*L$13)/MAX(ABS(D11),ABS(E11*L$12),ABS(F11*L$13)) | K11: Déterminant | L11: =L6*L7-L8*L8 | M11: =M6*M7-M8*M8
A12: 1 | B12: 1 | C12: 500/600/500 | D12: -53.262 | E12: 66.564 | F12: -62.515 | G12: =D12+E12+F12 | H12: =G12/MAX(ABS(D12),ABS(E12),ABS(F12)) | I12: =(D12+E12*L$12+F12*L$13)/MAX(ABS(D12),ABS(E12*L$12),ABS(F12*L$13)) | K12: x = 1/gB | L12: =(-L9*L7+L10*L8)/L11 | M12: =(-M9*M7+M10*M8)/M11
A13: 1 | B13: 2 | C13: 500/600/500 | D13: -53.771 | E13: 66.692 | F13: -62.826 | G13: =D13+E13+F13 | H13: =G13/MAX(ABS(D13),ABS(E13),ABS(F13)) | I13: =(D13+E13*L$12+F13*L$13)/MAX(ABS(D13),ABS(E13*L$12),ABS(F13*L$13)) | K13: y = 1/gC | L13: =(-L10*L6+L9*L8)/L11 | M13: =(-M10*M6+M9*M8)/M11
A14: 1 | B14: 3 | C14: 500/600/500 | D14: -53.918 | E14: 66.734 | F14: -62.567 | G14: =D14+E14+F14 | H14: =G14/MAX(ABS(D14),ABS(E14),ABS(F14)) | I14: =(D14+E14*L$12+F14*L$13)/MAX(ABS(D14),ABS(E14*L$12),ABS(F14*L$13)) | K14: gB ajusté (relatif à A) | L14: =1/L12 | M14: =1/M12
A15: 1 | B15: 1 | C15: 500/400/500 | D15: 16.726 | E15: -48.91 | F15: 64.618 | G15: =D15+E15+F15 | H15: =G15/MAX(ABS(D15),ABS(E15),ABS(F15)) | I15: =(D15+E15*L$12+F15*L$13)/MAX(ABS(D15),ABS(E15*L$12),ABS(F15*L$13)) | K15: gC ajusté (relatif à A) | L15: =1/L13 | M15: =1/M13
A16: 1 | B16: 2 | C16: 500/400/500 | D16: 52.071 | E16: -68.171 | F16: 52.914 | G16: =D16+E16+F16 | H16: =G16/MAX(ABS(D16),ABS(E16),ABS(F16)) | I16: =(D16+E16*L$12+F16*L$13)/MAX(ABS(D16),ABS(E16*L$12),ABS(F16*L$13)) | K16: gB imprimé par le script | L16: 0.6556 | M16: 1.0032
A17: 1 | B17: 3 | C17: 500/400/500 | D17: 51.973 | E17: -67.719 | F17: 53.369 | G17: =D17+E17+F17 | H17: =G17/MAX(ABS(D17),ABS(E17),ABS(F17)) | I17: =(D17+E17*L$12+F17*L$13)/MAX(ABS(D17),ABS(E17*L$12),ABS(F17*L$13)) | K17: gC imprimé par le script | L17: 1.1948 | M17: 1.0138
A18: 1 | B18: 1 | C18: 500/500/600 | D18: -50.527 | E18: -30.126 | F18: 112.527 | G18: =D18+E18+F18 | H18: =G18/MAX(ABS(D18),ABS(E18),ABS(F18)) | I18: =(D18+E18*L$12+F18*L$13)/MAX(ABS(D18),ABS(E18*L$12),ABS(F18*L$13)) | K18: Impulsions | L18: =COUNT(D6:D23) | M18: =COUNT(D27:D38)
A19: 1 | B19: 2 | C19: 500/500/600 | D19: -50.795 | E19: -30.454 | F19: 111.737 | G19: =D19+E19+F19 | H19: =G19/MAX(ABS(D19),ABS(E19),ABS(F19)) | I19: =(D19+E19*L$12+F19*L$13)/MAX(ABS(D19),ABS(E19*L$12),ABS(F19*L$13)) | K19: Erreur brute rms | L19: =SQRT(SUMSQ(H6:H23)/COUNT(H6:H23)) | M19: =SQRT(SUMSQ(H27:H38)/COUNT(H27:H38))
A20: 1 | B20: 3 | C20: 500/500/600 | D20: -50.471 | E20: -30.24 | F20: 112.311 | G20: =D20+E20+F20 | H20: =G20/MAX(ABS(D20),ABS(E20),ABS(F20)) | I20: =(D20+E20*L$12+F20*L$13)/MAX(ABS(D20),ABS(E20*L$12),ABS(F20*L$13)) | K20: Erreur brute pire | L20: =MAX(MAX(H6:H23),-MIN(H6:H23)) | M20: =MAX(MAX(H27:H38),-MIN(H27:H38))
A21: 1 | B21: 1 | C21: 500/500/400 | D21: 39.76 | E21: 36.11 | F21: -118.791 | G21: =D21+E21+F21 | H21: =G21/MAX(ABS(D21),ABS(E21),ABS(F21)) | I21: =(D21+E21*L$12+F21*L$13)/MAX(ABS(D21),ABS(E21*L$12),ABS(F21*L$13)) | K21: Erreur corrigée rms | L21: =SQRT(SUMSQ(I6:I23)/COUNT(I6:I23)) | M21: =SQRT(SUMSQ(I27:I38)/COUNT(I27:I38))
A22: 1 | B22: 2 | C22: 500/500/400 | D22: 47.828 | E22: 32.505 | F22: -120.911 | G22: =D22+E22+F22 | H22: =G22/MAX(ABS(D22),ABS(E22),ABS(F22)) | I22: =(D22+E22*L$12+F22*L$13)/MAX(ABS(D22),ABS(E22*L$12),ABS(F22*L$13)) | K22: Erreur corrigée pire | L22: =MAX(MAX(I6:I23),-MIN(I6:I23)) | M22: =MAX(MAX(I27:I38),-MIN(I27:I38))
A23: 1 | B23: 3 | C23: 500/500/400 | D23: 50.171 | E23: 31.844 | F23: -120.995 | G23: =D23+E23+F23 | H23: =G23/MAX(ABS(D23),ABS(E23),ABS(F23)) | I23: =(D23+E23*L$12+F23*L$13)/MAX(ABS(D23),ABS(E23*L$12),ABS(F23*L$13)) | K23: Sources : gains_run1.txt, gains_run2.txt (ligne JSON). Police bleue : valeurs imprimées par le script, pour contrôle des formules.
A25: Run 2 : même campagne rejouée avec la correction de gain active dans le firmware (courants déjà corrigés). | K25: Lecture
A26: Run | B26: # | C26: Configuration (‰) | D26: dA (counts) | E26: dB (counts) | F26: dC (counts) | G26: Σ brute (counts) | H26: Erreur brute | I26: Erreur corrigée | K26: Run 1 : gB = 0,656 et gC = 1,195 ; la somme passe de 41,8 % rms (74,8 % pire) brute à 4,6 % (7,3 %) après correction.
A27: 2 | B27: 1 | C27: 600/500/500 | D27: 122.748 | E27: -65.608 | F27: -63.012 | G27: =D27+E27+F27 | H27: =G27/MAX(ABS(D27),ABS(E27),ABS(F27)) | I27: =(D27+E27*M$12+F27*M$13)/MAX(ABS(D27),ABS(E27*M$12),ABS(F27*M$13)) | K27: Run 2 (firmware corrigé) : gains ré-ajustés 1,003 et 1,014 — la correction est juste à ~1 % ; somme 4,5 % rms / 5,8 % pire telle que mesurée.
A28: 2 | B28: 2 | C28: 600/500/500 | D28: 122.925 | E28: -64.858 | F28: -63.676 | G28: =D28+E28+F28 | H28: =G28/MAX(ABS(D28),ABS(E28),ABS(F28)) | I28: =(D28+E28*M$12+F28*M$13)/MAX(ABS(D28),ABS(E28*M$12),ABS(F28*M$13)) | K28: Run 2, colonne « Erreur corrigée » : le ré-ajustement n'améliore plus rien (4,4 % / 6,6 %) — le résidu n'est plus un gain.
A29: 2 | B29: 1 | C29: 400/500/500 | D29: -125.724 | E29: 57.89 | F29: 60.515 | G29: =D29+E29+F29 | H29: =G29/MAX(ABS(D29),ABS(E29),ABS(F29)) | I29: =(D29+E29*M$12+F29*M$13)/MAX(ABS(D29),ABS(E29*M$12),ABS(F29*M$13)) | K29: Run 1, 500/400/500 #1 : dA = 16,7 au lieu de ~52 (rotor probablement pas encore aligné) — conservé dans l'ajustement, comme dans le script d'origine.
A30: 2 | B30: 2 | C30: 400/500/500 | D30: -123.705 | E30: 65.777 | F30: 51.634 | G30: =D30+E30+F30 | H30: =G30/MAX(ABS(D30),ABS(E30),ABS(F30)) | I30: =(D30+E30*M$12+F30*M$13)/MAX(ABS(D30),ABS(E30*M$12),ABS(F30*M$13))
A31: 2 | B31: 1 | C31: 500/600/500 | D31: -64.261 | E31: 120.5 | F31: -62.324 | G31: =D31+E31+F31 | H31: =G31/MAX(ABS(D31),ABS(E31),ABS(F31)) | I31: =(D31+E31*M$12+F31*M$13)/MAX(ABS(D31),ABS(E31*M$12),ABS(F31*M$13))
A32: 2 | B32: 2 | C32: 500/600/500 | D32: -63.983 | E32: 121.166 | F32: -62.351 | G32: =D32+E32+F32 | H32: =G32/MAX(ABS(D32),ABS(E32),ABS(F32)) | I32: =(D32+E32*M$12+F32*M$13)/MAX(ABS(D32),ABS(E32*M$12),ABS(F32*M$13))
A33: 2 | B33: 1 | C33: 500/400/500 | D33: 61.816 | E33: -123.041 | F33: 54.242 | G33: =D33+E33+F33 | H33: =G33/MAX(ABS(D33),ABS(E33),ABS(F33)) | I33: =(D33+E33*M$12+F33*M$13)/MAX(ABS(D33),ABS(E33*M$12),ABS(F33*M$13))
A34: 2 | B34: 2 | C34: 500/400/500 | D34: 62.619 | E34: -123.341 | F34: 53.932 | G34: =D34+E34+F34 | H34: =G34/MAX(ABS(D34),ABS(E34),ABS(F34)) | I34: =(D34+E34*M$12+F34*M$13)/MAX(ABS(D34),ABS(E34*M$12),ABS(F34*M$13))
A35: 2 | B35: 1 | C35: 500/500/600 | D35: -61.026 | E35: -50.799 | F35: 112.321 | G35: =D35+E35+F35 | H35: =G35/MAX(ABS(D35),ABS(E35),ABS(F35)) | I35: =(D35+E35*M$12+F35*M$13)/MAX(ABS(D35),ABS(E35*M$12),ABS(F35*M$13))
A36: 2 | B36: 2 | C36: 500/500/600 | D36: -61.01 | E36: -52.34 | F36: 112.837 | G36: =D36+E36+F36 | H36: =G36/MAX(ABS(D36),ABS(E36),ABS(F36)) | I36: =(D36+E36*M$12+F36*M$13)/MAX(ABS(D36),ABS(E36*M$12),ABS(F36*M$13))
A37: 2 | B37: 1 | C37: 500/500/400 | D37: 66.315 | E37: 49.805 | F37: -120.191 | G37: =D37+E37+F37 | H37: =G37/MAX(ABS(D37),ABS(E37),ABS(F37)) | I37: =(D37+E37*M$12+F37*M$13)/MAX(ABS(D37),ABS(E37*M$12),ABS(F37*M$13))
A38: 2 | B38: 2 | C38: 500/500/400 | D38: 59.436 | E38: 56.812 | F38: -121.192 | G38: =D38+E38+F38 | H38: =G38/MAX(ABS(D38),ABS(E38),ABS(F38)) | I38: =(D38+E38*M$12+F38*M$13)/MAX(ABS(D38),ABS(E38*M$12),ABS(F38*M$13))

Sheet Zéro courant
A1: Zéro de la chaîne de courant au repos
A2: Relevé console : 10 240 échantillons par voie, échantillonnage 47,5 cycles, sorties coupées (hors CAL) ; valeurs ADC brutes (mi-échelle = 2048)
A4: Voie | B4: Médiane (ADC) | C4: Min (ADC) | D4: Max (ADC) | E4: Moyenne (ADC) | F4: Part exactement à 2048 | G4: Médiane − 2048 (counts) | H4: Étendue max−min (counts) | I4: Courant centré au repos après correction (counts)
A5: A | B5: 2062 | C5: 1990 | D5: 2112 | E5: 2061 | F5: n.r. | G5: =B5-2048 | H5: =D5-C5 | I5: -1
A6: B | B6: 2054 | C6: 2048 | D6: 2081 | E6: n.r. | F6: 0.117 | G6: =B6-2048 | H6: =D6-C6 | I6: 0
A7: C | B7: 2048 | C7: 2048 | D7: 2101 | E7: n.r. | F7: 0.952 | G7: =B7-2048 | H7: =D7-C7 | I7: 0
A9: n.r. : non relevé. Police bleue : relevé console ; noire : calcul.
A11: Lecture
A12: Aucune voie ne descend sous 2048 au repos (sauf A, min 1990), alors qu'en charge elles descendent bien en dessous : ce n'est ni un plancher dur ni un offset ADC configuré.
A13: Accumulation exactement sur 2048 : 95,2 % des échantillons de C, 11,7 % de B. Hypothèse non vérifiée : écrêtage de la sortie de l'ampli du DRV8304 à la référence avec un offset d'entrée légèrement négatif.
A14: Conséquence : zone morte de quelques counts autour de zéro, surtout sur C. Sans effet sur la limite de surintensité ni sur les étapes 8 et 9 ; à comprendre avant la boucle de courant.
A15: Le zéro de fonctionnement est la lecture hors CAL (transistors bas conducteurs), ≈ 16/8/9 counts au-dessus du zéro CAL selon STATUS.md ; il est désormais mesuré ainsi au démarrage.

Sheet Étape 7 — R, L, échelle
A1: Étape 7 — résistance, inductance et échelle absolue du courant
A2: Paliers de 10 s sous watchdog, 2026-09-26 ; courants moyens du firmware en counts corrigés (échelle voie C) ; ampèremètre en série avec l'alimentation (relevé console + ampèremètre)
A4: Entrées (relevé)
A5: Palier | B5: Duty A (‰) | C5: Duty B (‰) | D5: Duty C (‰) | E5: Ia (counts corr.) | F5: Ib (counts corr.) | G5: Ic (counts corr.) | H5: Σ (counts) | I5: I alim. ampèremètre (mA)
A6: Repos | B6: — | C6: — | D6: — | E6: 3.6 | F6: 0 | G6: 0 | H6: =E6+F6+G6 | I6: 30
A7: Palier 1 | B7: 600 | C7: 500 | D7: 500 | E7: 124.9 | F7: -62.9 | G7: -62 | H7: =E7+F7+G7 | I7: 51
A8: Palier 2 | B8: 550 | C8: 500 | D8: 500 | E8: 50.2 | F8: -12.8 | G8: -24.5 | H8: =E8+F8+G8 | I8: 35
A10: Paramètre | B10: Valeur | C10: Unité | E10: Calculs
A11: Tension moteur Vmot | B11: 14.8 | C11: V | E11: Grandeur | F11: Valeur | G11: Unité | H11: Formule / remarque
A12: Gain appliqué voie A | B12: 1195 | C12: ‰ | E12: Écart commandé palier 1 | F12: =(B7-C7)/1000 | G12: — | H12: (duty A − duty B)/1000
A13: Gain appliqué voie B | B13: 1822 | C13: ‰ | E13: Écart commandé palier 2 | F13: =(B8-C8)/1000 | G13: —
A14: Gain appliqué voie C | B14: 1000 | C14: ‰ | E14: Rapport des courants Ia1/Ia2 | F14: =E7/E8 | G14: — | H14: lu sur les courants
A15: Offset voie A | B15: 2051 | C15: ADC | E15: Perte de temps mort δ (fraction de Vbus) | F15: =(F14*F13-F12)/(F14-1) | G15: — | H15: (e1−δ)/(e2−δ) = Ia1/Ia2
A16: Offset voie B | B16: 2055 | C16: ADC | E16: Perte de temps mort en tension | F16: =F15*B11 | G16: V | H16: δ × Vmot
A17: Offset voie C | B17: 2048 | C17: ADC | E17: Écart effectif palier 1 | F17: =F12-F15 | G17: — | H17: e1 − δ
A18: τ retenu (montée du courant) | B18: 0.3 | C18: ms | E18: Écart effectif palier 2 | F18: =F13-F15 | G18: — | H18: e2 − δ
A19: Shunt nominal | B19: 10 | C19: mΩ | E19: Rapport des écarts effectifs | F19: =F17/F18 | G19: — | H19: à comparer au rapport des courants
A20: Incertitude sur l'échelle (lecture de l'ampèremètre) | B20: 0.15 | C20: ± | E20: ΔI alim. palier 1 (− repos) | F20: =I7-I6 | G20: mA
E21: ΔI alim. palier 2 (− repos) | F21: =I8-I6 | G21: mA
E22: Ia palier 2 | F22: =(F20-F21)/(F17*F14-F18) | G22: mA | H22: ΔI = e_eff × Ia + Ig, Ia1 = r·Ia2
E23: Ia palier 1 | F23: =F14*F22 | G23: mA
E24: Courant de grilles Ig | F24: =F21-F18*F22 | G24: mA
E25: Échelle absolue (voie C = counts corrigés) | F25: =F23/E7 | G25: mA / count | H25: Ia1 / Ia1 counts
E26: Échelle nominale (20 V/V × 10 mΩ) | F26: =Conditions!B25 | G26: mA / count
E27: Échelle voie A brute | F27: =F25*B12/1000 | G27: mA / count | H27: échelle × gain appliqué
E28: Échelle voie B brute | F28: =F25*B13/1000 | G28: mA / count
E29: Échelle voie C brute | F29: =F25*B14/1000 | G29: mA / count
E30: Sur-lecture voie A | F30: =F26/F27 | G30: × | H30: nominal / réel
E31: Sur-lecture voie B | F31: =F26/F28 | G31: ×
E32: Sur-lecture voie C | F32: =F26/F29 | G32: ×
E33: Shunt équivalent vu, voie A | F33: =F30*B19 | G33: mΩ | H33: 10 mΩ × sur-lecture
E34: Shunt équivalent vu, voie B | F34: =F31*B19 | G34: mΩ
E35: Shunt équivalent vu, voie C | F35: =F32*B19 | G35: mΩ
E36: ΔV entre paliers | F36: =(F12-F13)*B11 | G36: V | H36: le temps mort s'annule
E37: R entre A et (B∥C) | F37: =F36/((F23-F22)/1000) | G37: Ω | H37: ΔV / ΔIa
E38: R par phase | F38: =F37*2/3 | G38: Ω | H38: R_A + R/2 = 1,5 R
E39: Puissance fournie au moteur, palier 1 | F39: =F17*B11*F23/1000 | G39: W | H39: e_eff1 × Vmot × Ia1
E40: Pertes Joule I²R, palier 1 | F40: =(F23/1000)^2*F37 | G40: W | H40: Ia1² × R_A,B∥C
E41: L entre A et (B∥C) | F41: =B18/1000*F37*1000 | G41: mH | H41: τ × R
E42: L par phase | F42: =F41*2/3 | G42: mH | H42: ±25 %
...

Sheet Étapes 9 et 8
A1: Étapes 9 et 8 — paires de pôles et décalage électrique
A2: Champ fixe 200 ms à θe (pas 30°, 2 tours aller puis 2 retour), amplitude 56 ‰ autour de 500 ; θm lu par l'AS5600 à 170 ms (relatif)
A4: Pas | B4: Sens | C4: θe (°él.) | D4: θm essai 1 (rad) | E4: θm essai 1 (°méca) | F4: θm essai 2 (rad) | G4: θm essai 2 (°méca) | H4: θm essai 3 (rad) | I4: θm essai 3 (°méca) | J4: θm essai 4 (rad) | K4: θm essai 4 (°méca) | M4: θe aller (°él.) | N4: Essai 1 aller (°méca) | O4: θe retour (°él.) | P4: Essai 1 retour (°méca)
A5: 0 | B5: aller | C5: 0 | D5: 0.134 | E5: =DEGREES(D5) | F5: 0.128 | G5: =DEGREES(F5) | H5: 0.128 | I5: =DEGREES(H5) | J5: 0 | K5: =DEGREES(J5) | M5: =C5 | N5: =E5 | O5: =C30 | P5: =E30
A6: 1 | B6: aller | C6: 30 | D6: 0.058 | E6: =DEGREES(D6) | F6: 0.056 | G6: =DEGREES(F6) | H6: 0.056 | I6: =DEGREES(H6) | J6: -0.07 | K6: =DEGREES(J6) | M6: =C6 | N6: =E6 | O6: =C31 | P6: =E31
A7: 2 | B7: aller | C7: 60 | D7: -0.006 | E7: =DEGREES(D7) | F7: -0.007 | G7: =DEGREES(F7) | H7: -0.007 | I7: =DEGREES(H7) | J7: -0.136 | K7: =DEGREES(J7) | M7: =C7 | N7: =E7 | O7: =C32 | P7: =E32
A8: 3 | B8: aller | C8: 90 | D8: -0.095 | E8: =DEGREES(D8) | F8: -0.098 | G8: =DEGREES(F8) | H8: -0.096 | I8: =DEGREES(H8) | J8: -0.227 | K8: =DEGREES(J8) | M8: =C8 | N8: =E8 | O8: =C33 | P8: =E33
A9: 4 | B9: aller | C9: 120 | D9: -0.158 | E9: =DEGREES(D9) | F9: -0.159 | G9: =DEGREES(F9) | H9: -0.161 | I9: =DEGREES(H9) | J9: -0.288 | K9: =DEGREES(J9) | M9: =C9 | N9: =E9 | O9: =C34 | P9: =E34
A10: 5 | B10: aller | C10: 150 | D10: -0.216 | E10: =DEGREES(D10) | F10: -0.216 | G10: =DEGREES(F10) | H10: -0.217 | I10: =DEGREES(H10) | J10: -0.346 | K10: =DEGREES(J10) | M10: =C10 | N10: =E10 | O10: =C35 | P10: =E35
A11: 6 | B11: aller | C11: 180 | D11: -0.288 | E11: =DEGREES(D11) | F11: -0.289 | G11: =DEGREES(F11) | H11: -0.289 | I11: =DEGREES(H11) | J11: -0.417 | K11: =DEGREES(J11) | M11: =C11 | N11: =E11 | O11: =C36 | P11: =E36
A12: 7 | B12: aller | C12: 210 | D12: -0.388 | E12: =DEGREES(D12) | F12: -0.389 | G12: =DEGREES(F12) | H12: -0.389 | I12: =DEGREES(H12) | J12: -0.518 | K12: =DEGREES(J12) | M12: =C12 | N12: =E12 | O12: =C37 | P12: =E37
A13: 8 | B13: aller | C13: 240 | D13: -0.449 | E13: =DEGREES(D13) | F13: -0.45 | G13: =DEGREES(F13) | H13: -0.45 | I13: =DEGREES(H13) | J13: -0.579 | K13: =DEGREES(J13) | M13: =C13 | N13: =E13 | O13: =C38 | P13: =E38
A14: 9 | B14: aller | C14: 270 | D14: -0.543 | E14: =DEGREES(D14) | F14: -0.544 | G14: =DEGREES(F14) | H14: -0.544 | I14: =DEGREES(H14) | J14: -0.673 | K14: =DEGREES(J14) | M14: =C14 | N14: =E14 | O14: =C39 | P14: =E39
A15: 10 | B15: aller | C15: 300 | D15: -0.619 | E15: =DEGREES(D15) | F15: -0.621 | G15: =DEGREES(F15) | H15: -0.621 | I15: =DEGREES(H15) | J15: -0.75 | K15: =DEGREES(J15) | M15: =C15 | N15: =E15 | O15: =C40 | P15: =E40
A16: 11 | B16: aller | C16: 330 | D16: -0.67 | E16: =DEGREES(D16) | F16: -0.679 | G16: =DEGREES(F16) | H16: -0.674 | I16: =DEGREES(H16) | J16: -0.803 | K16: =DEGREES(J16) | M16: =C16 | N16: =E16 | O16: =C41 | P16: =E41
... A28: 23 | B28: aller | C28: 690 | D28: -1.57 | E28: =DEGREES(D28) | F28: -1.572 | G28: =DEGREES(F28) | H28: -1.572 | I28: =DEGREES(H28) | J28: -1.701 | K28: =DEGREES(J28) | M28: =C28 | N28: =E28 | O28: =C53 | P28: =E53
A29: 24 | B29: aller | C29: 720 | D29: -1.649 | E29: =DEGREES(D29) | F29: -1.65 | G29: =DEGREES(F29) | H29: -1.65 | I29: =DEGREES(H29) | J29: -1.779 | K29: =DEGREES(J29) | M29: =C29 | N29: =E29
A30: 25 | B30: retour | C30: 690 | D30: -1.573 | E30: =DEGREES(D30) | F30: -1.575 | G30: =DEGREES(F30) | H30: -1.575 | I30: =DEGREES(H30) | J30: -1.704 | K30: =DEGREES(J30)
A31: 26 | B31: retour | C31: 660 | D31: -1.521 | E31: =DEGREES(D31) | F31: -1.523 | G31: =DEGREES(F31) | H31: -1.523 | I31: =DEGREES(H31) | J31: -1.652 | K31: =DEGREES(J31)
A32: 27 | B32: retour | C32: 630 | D32: -1.457 | E32: =DEGREES(D32) | F32: -1.46 | G32: =DEGREES(F32) | H32: -1.46 | I32: =DEGREES(H32) | J32: -1.587 | K32: =DEGREES(J32)
A33: 28 | B33: retour | C33: 600 | D33: -1.365 | E33: =DEGREES(D33) | F33: -1.366 | G33: =DEGREES(F33) | H33: -1.366 | I33: =DEGREES(H33) | J33: -1.495 | K33: =DEGREES(J33)
A34: 29 | B34: retour | C34: 570 | D34: -1.294 | E34: =DEGREES(D34) | F34: -1.296 | G34: =DEGREES(F34) | H34: -1.296 | I34: =DEGREES(H34) | J34: -1.425 | K34: =DEGREES(J34)
A35: 30 | B35: retour | C35: 540 | D35: -1.204 | E35: =DEGREES(D35) | F35: -1.205 | G35: =DEGREES(F35) | H35: -1.205 | I35: =DEGREES(H35) | J35: -1.334 | K35: =DEGREES(J35)
A36: 31 | B36: retour | C36: 510 | D36: -1.142 | E36: =DEGREES(D36) | F36: -1.144 | G36: =DEGREES(F36) | H36: -1.144 | I36: =DEGREES(H36) | J36: -1.271 | K36: =DEGREES(J36)
A37: 32 | B37: retour | C37: 480 | D37: -1.086 | E37: =DEGREES(D37) | F37: -1.086 | G37: =DEGREES(F37) | H37: -1.087 | I37: =DEGREES(H37) | J37: -1.214 | K37: =DEGREES(J37)
A38: 33 | B38: retour | C38: 450 | D38: -1.004 | E38: =DEGREES(D38) | F38: -1.006 | G38: =DEGREES(F38) | H38: -1.006 | I38: =DEGREES(H38) | J38: -1.135 | K38: =DEGREES(J38)
A39: 34 | B39: retour | C39: 420 | D39: -0.926 | E39: =DEGREES(D39) | F39: -0.926 | G39: =DEGREES(F39) | H39: -0.926 | I39: =DEGREES(H39) | J39: -1.055 | K39: =DEGREES(J39)
A40: 35 | B40: retour | C40: 390 | D40: -0.846 | E40: =DEGREES(D40) | F40: -0.848 | G40: =DEGREES(F40) | H40: -0.848 | I40: =DEGREES(H40) | J40: -0.977 | K40: =DEGREES(J40)
A41: 36 | B41: retour | C41: 360 | D41: -0.745 | E41: =DEGREES(D41) | F41: -0.747 | G41: =DEGREES(F41) | H41: -0.747 | I41: =DEGREES(H41) | J41: -0.875 | K41: =DEGREES(J41)
... A53: 48 | B53: retour | C53: 0 | D53: 0.131 | E53: =DEGREES(D53) | F53: 0.13 | G53: =DEGREES(F53) | H53: 0.13 | I53: =DEGREES(H53) | J53: 0.001 | K53: =DEGREES(J53)
A58: Résultats par essai
A59: Essai | B59: Fichier | C59: Pente aller (°méca / tour élec.) | D59: Paires de pôles p = 360/|pente| | E59: p entier | F59: Sens | G59: Retour au départ (°méca) | H59: Écart aller/retour max (°méca) | I59: φ étape 8 (°élec) | J59: Dispersion φ rms (°élec) | K59: Dispersion φ pire (°élec) | L59: Remarque
A60: 1 | B60: step9_1790434514548.csv | C60: =SLOPE(E5:E29,$C$5:$C$29)*360 | D60: =360/ABS(C60) | E60: =ROUND(D60,0) | F60: =IF(C60<0,"inverse","direct") | G60: =E53-E5 | H60: =MAX(ABS(E5-E53),ABS(E6-E52),ABS(E7-E51),ABS(E8-E50),ABS(E9-E49),ABS(E10-E48),ABS(E11-E47),ABS(E12-E46),ABS(E13-E45),ABS(E14-E44),ABS(E15-E43),ABS(E16-E42),ABS(E17-E41),ABS(E18-E40),ABS(E19-E39),ABS(E20-E38),ABS(E21-E37),ABS(E22-E36),ABS(E23-E35),ABS(E24-E34),ABS(E25-E33),ABS(E26-E32),ABS(E27-E31),ABS(E28-E30)) | I60: non relevé | J60: — | K60: —
A61: 2 | B61: step9_1790434555574.csv | C61: =SLOPE(G5:G29,$C$5:$C$29)*360 | D61: =360/ABS(C61) | E61: =ROUND(D61,0) | F61: =IF(C61<0,"inverse","direct") | G61: =G53-G5 | H61: =MAX(ABS(G5-G53),ABS(G6-G52),ABS(G7-G51),ABS(G8-G50),ABS(G9-G49),ABS(G10-G48),ABS(G11-G47),ABS(G12-G46),ABS(G13-G45),ABS(G14-G44),ABS(G15-G43),ABS(G16-G42),ABS(G17-G41),ABS(G18-G40),ABS(G19-G39),ABS(G20-G38),ABS(G21-G37),ABS(G22-G36),ABS(G23-G35),ABS(G24-G34),ABS(G25-G33),ABS(G26-G32),ABS(G27-G31),ABS(G28-G30)) | I61: 178 | J61: 5.2 | K61: 10,3 à 10,9
A62: 3 | B62: step9_1790434569276.csv | C62: =SLOPE(I5:I29,$C$5:$C$29)*360 | D62: =360/ABS(C62) | E62: =ROUND(D62,0) | F62: =IF(C62<0,"inverse","direct") | G62: =I53-I5 | H62: =MAX(ABS(I5-I53),ABS(I6-I52),ABS(I7-I51),ABS(I8-I50),ABS(I9-I49),ABS(I10-I48),ABS(I11-I47),ABS(I12-I46),ABS(I13-I45),ABS(I14-I44),ABS(I15-I43),ABS(I16-I42),ABS(I17-I41),ABS(I18-I40),ABS(I19-I39),ABS(I20-I38),ABS(I21-I37),ABS(I22-I36),ABS(I23-I35),ABS(I24-I34),ABS(I25-I33),ABS(I26-I32),ABS(I27-I31),ABS(I28-I30)) | I62: 178.1 | J62: 5.2 | K62: 10,3 à 10,9
A63: 4 | B63: step9_1790434600992.csv | C63: =SLOPE(K5:K29,$C$5:$C$29)*360 | D63: =360/ABS(C63) | E63: =ROUND(D63,0) | F63: =IF(C63<0,"inverse","direct") | G63: =K53-K5 | H63: =MAX(ABS(K5-K53),ABS(K6-K52),ABS(K7-K51),ABS(K8-K50),ABS(K9-K49),ABS(K10-K48),ABS(K11-K47),ABS(K12-K46),ABS(K13-K45),ABS(K14-K44),ABS(K15-K43),ABS(K16-K42),ABS(K17-K41),ABS(K18-K40),ABS(K19-K39),ABS(K20-K38),ABS(K21-K37),ABS(K22-K36),ABS(K23-K35),ABS(K24-K34),ABS(K25-K33),ABS(K26-K32),ABS(K27-K31),ABS(K28-K30)) | I63: 178.1 | J63: 5.2 | K63: 10,3 à 10,9 | L63: après redémarrage de la carte
A64: Moy. | C64: =AVERAGE(C60:C63) | D64: =AVERAGE(D60:D63) | I64: =AVERAGE(I61:I63)
A65: Étendue | C65: =MAX(C60:C63)-MIN(C60:C63) | D65: =MAX(D60:D63)-MIN(D60:D63) | I65: =MAX(I61:I63)-MIN(I61:I63)
A67: Pente attendue pour 7 paires : −360/7 = −51,43 °méca par tour électrique. φ est calculé sur l'angle brut absolu RAW_ANGLE (0–4095), absent des CSV : valeurs du relevé console (police bleue), avec θélec = φ − 7·θméca.
A68: Dispersion φ : 5,2° rms communiquée comme valeur intra-essai commune ; pire écart 10,3 à 10,9° selon l'essai (répartition par essai non fournie). Écart aller/retour : max |θm aller − θm retour| au même θe (0 à 690°) ; résolution 1 mrad = 0,057°.

Sheet Méthode
A1: Méthode, sources et points de vigilance
A2: Comment chaque chiffre a été obtenu
A4: Grandeur | B4: Obtention | C4: Source
A5: Deltas de courant (étape 5) | B5: Par voie : moyenne des échantillons 30–50 ms (régime ; impulsion de 50 ms démarrant ~2 ms après le début de la capture) moins moyenne 60–100 ms (repos, après la coupure). Counts centrés ; 1 count ≈ 4,03 mA à l'échelle nominale 20 V/V × 10 mΩ. | C5: step5_<a>_<b>_<c>_50ms_<horodatage>.csv (20 fichiers, 2048 points à 20 kHz)
A6: Erreur de somme | B6: (dA + dB + dC) / max(|dA|,|dB|,|dC|). Sans objet à écart nul (dénominateur ~1 count). | C6: Formules des onglets Étape 5 et Gains
A7: Séries 1 et 2 | B7: Série 1 : échantillonnage ADC 6,5 cycles (180 ns). Série 2 : 47,5 cycles (1,32 µs), chaque configuration jouée deux fois, seule la seconde est retenue (rotor aligné). Aucune correction de gain dans les deux séries. | C7: Horodatages des fichiers
A8: Gains par voie | B8: Moindres carrés sous Ia+Ib+Ic = 0 : min Σ (dA + x·dB + y·dC)², gB = 1/x, gC = 1/y, sur 18 impulsions (6 configurations × 3 répétitions retenues). Recalculés dans l'onglet Gains par SUMPRODUCT et comparés aux valeurs du script. | C8: gains_run1.txt (lignes et JSON), script gains.ts
A9: Vérification des gains | B9: Même campagne rejouée firmware corrigé (12 impulsions, 2 par configuration) : gains ré-ajustés ≈ 1 et somme brute 4,5 % rms. | C9: gains_run2.txt
A10: Zéro au repos | B10: Statistiques sur 10 240 échantillons par voie, sorties coupées, hors CAL. | C10: Relevé console
A11: Paires de pôles (étape 9) | B11: Régression linéaire θm (°) sur θe (°) sur l'aller seul (25 points, 0 à 720°), × 360 → degrés mécaniques par tour électrique ; p = 360/|pente|. Recalculé par SLOPE dans l'onglet. | C11: step9_<horodatage>.csv (4 fichiers), script poles.ts
A12: Décalage électrique (étape 8) | B12: φ = moyenne circulaire de (θe + 7·θraw) sur tous les points de l'essai, θraw = RAW_ANGLE × 360/4096 ; dispersion = écart quadratique et pire écart autour de φ. | C12: Relevé console (angle brut absent des CSV)
A13: Rails, boucle, limites, résistance | B13: Relevés console ; R ≈ 7 Ω de A vers B∥C ⇒ ≈ 4,7 Ω par phase (× 2/3). | C13: Relevé console, STATUS.md
A14: Échelle absolue, R et L (étape 7) | B14: Deux paliers de 10 s (600 et 550 ‰ sur A) : le rapport des courants donne la perte de temps mort δ ; (I_alim − I_repos) = (écart − δ) × Ia + Ig, résolu sur les deux paliers ⇒ Ia en mA, d'où l'échelle. R = ΔV/ΔIa entre paliers (temps mort éliminé) ; L = τ × R, τ lu sur la montée du courant de la capture 1790433425069. Tout est recalculé par formules dans l'onglet. | C14: Relevé console + ampèremètre (communiqué) ; step5_600_500_500_50ms_1790433425069.csv
A15: Capture typique | B15: Fichier 1790433425069 sous-échantillonné 1/4 (512 points) pour alléger le classeur. | C15: step5_600_500_500_50ms_1790433425069.csv
A17: Points de vigilance sur les données
A18: 1. | B18: Série 1, rampe A dominante : l'erreur de somme n'est pas monotone — 9,1 % à 30 ‰, 41,0 % à 50 ‰, 15,3 % à 70 ‰, 23,8 % à 100 ‰. Le point à 50 ‰ coïncide avec un rotor qui bouge de 0,15 rad pendant l'impulsion. STATUS.md écrit « la somme se tenait à 30 ‰ d'écart » : vrai à 30 ‰, pas à 50 ‰.
A19: 2. | B19: Série 1, 600/500/500 : la méthode donne 23,8 % ; STATUS.md écrit « 22 % à 100 ‰ ». Même ordre de grandeur, écart probablement dû à une fenêtre de moyennage différente lors de l'essai. Série 2 retenu : 4,0 %, cohérent avec « passe à 4 % ».
A20: 3. | B20: Run 1 des gains, 500/400/500 #1 : dA = 16,7 counts au lieu de ~52 pour les deux autres répétitions — rotor probablement pas aligné. L'impulsion est incluse dans l'ajustement (comme dans le script) et fait le pire de l'erreur corrigée (7,3 %).
A21: 4. | B21: STATUS.md, tableau de l'étape 5 : gain C « 1,18 » (première estimation) ; la campagne donne 1,195, valeur retenue dans le firmware.
A22: 5. | B22: STATUS.md, liste des protections : « 0 à 900 ‰ par bras » ; le plafond a ensuite été abaissé à 800 ‰ (même section, plus bas). La valeur en vigueur est 800 ‰.
A23: 6. | B23: Étape 9 : STATUS.md écrit « l'aller et le retour se superposent à moins de 0,35° ». Vrai pour les essais 1 et 3 (0,34°) ; les essais 2 et 4 vont jusqu'à 0,46° (8 mrad). Le retour au départ (0,06 à 0,17°) est conforme.
A24: 7. | B24: Étape 8 : « 10,9° au pire » dans STATUS.md, 10,3 à 10,9° selon l'essai dans le relevé : compatible. Pas de φ relevé pour l'essai 1.
A25: 8. | B25: Résistance : ≈ 7 Ω A→(B∥C) (≈ 4,7 Ω par phase) dans STATUS.md et le relevé console, contre 5,42–5,44 Ω (≈ 3,6 Ω) à l'étape 7. L'estimation initiale reposait sur l'échelle nominale et ignorait le temps mort ; la valeur de l'étape 7 la remplace. De même, STATUS.md attend « ≈ 43 mA à 100 ‰ » au courant d'alimentation : mesuré ≈ 21 mA au-dessus du repos (écart effectif 8,4 % × 227 mA + Ig).
A26: 9. | B26: τ : la fin d'impulsion (entre 51,90 et 51,95 ms) place le début entre 1,90 et 1,95 ms ; τ vaut alors de 0,34 à 0,27 ms. Un ajustement à t0 libre donne ≈ 0,29 ms ; la valeur 0,344 ms communiquée correspond à t0 = 1,90 ms. τ ≈ 0,3 ms retenu, L à ±25 %.
A27: 10. | B27: Étape 7 : recalculées par formules à partir des entrées arrondies, les valeurs diffèrent un peu des chiffres communiqués (Ia1 228 contre 227 mA, R 5,42 contre 5,44 Ω, échelle 1,83 contre 1,82 mA/count) — écarts d'arrondi, très en deçà de l'incertitude de ±15 %.
A28: 11. | B28: Étape 7, repos : Ia = 3,6 counts corrigés, contre « −1, 0, 0 » au repos dans le relevé de l'étape 5 — petite dérive du zéro de A entre les deux relevés.
A29: 12. | B29: Durée ISR : 3,57 µs typique / 6,09 µs pire le 2026-09-26, contre 2,60 µs au pire à l'étape 6 (2026-09-21) — cohérent avec l'ajout de code depuis, pas une contradiction.
A31: Fichiers sources
A32: Données brutes : répertoire scratchpad de la session (hors dépôt) C:\Users\echan\AppData\Local\Temp\claude\H--Repos-a2n-bldc\29db5842-4784-4b0d-9a4a-eb4df09ec258\scratchpad\
A33: Contexte : H:\Repos\a2n-bldc\STATUS.md (Étape 5, Étapes 9 et 8, Stabilisation du firmware, Décisions) ; controller-2/AGENTS.md §5 pour les critères.
